 <?xml version='1.0'?>
    <sdf version='1.4'>
      <model name="mrp2">
      <static>false</static>
      <link name='chassis'>
          <pose>0 0 0 0 0 0</pose>
          <inertial>
            <pose>0.01173 0.00025945 0.17611 0 -0 0</pose>
            <mass>18.68574</mass>
            <inertia>
              <ixx>0.46880</ixx>
              <ixy>-0.05230</ixy>
              <ixz>-0.00522</ixz>
              <iyy>0.82975</iyy>
              <iyz>0.00253</iyz>
              <izz>0.61354</izz>
            </inertia>
          </inertial>

          <collision name='collision'>
            <pose>0 0 0 0 0 0</pose>
            <geometry>
              <mesh>
                <scale>1 1 1</scale>
                <uri>model://mrp2/meshes/base_link.stl</uri>
              </mesh>
              <!--<box>
                <size>.62 .534 .297</size>
              </box>-->
            </geometry>
            <surface>
              <friction>
                <ode>
                  <mu>0</mu>
                  <mu2>0</mu2>
                  <slip1>1</slip1>
                  <slip2>1</slip2>
                </ode>
              </friction>
            </surface>
          </collision>

          <visual name='visual'>
            <geometry>
              <mesh>
                <scale>1 1 1</scale>
                <uri>model://mrp2/meshes/base_link.stl</uri>
              </mesh>
            </geometry>
          </visual>

        <collision name='caster_fr_collision'>
          <pose>0.1825 0.14 0.035 0 0 0</pose>
          <geometry>
              <sphere>
              <radius>.0375</radius>
            </sphere>
          </geometry>

          <surface>
            <friction>
              <ode>
                <mu>0.1</mu>
                <mu2>0.1</mu2>
                <slip1>0.8</slip1>
                <slip2>0.6</slip2>
              </ode>
            </friction>
          </surface>
        </collision>

        <!--<visual name='caster_fr_visual'>
          <pose>0.1825 0.14 0.035 0 0 0</pose>
          <geometry>
            <sphere>
              <radius>.0375</radius>
            </sphere>
          </geometry>
        </visual>-->

        <collision name='caster_fl_collision'>
          <pose>0.1825 -0.14 0.035 0 0 0</pose>
          <geometry>
              <sphere>
              <radius>.0375</radius>
            </sphere>
          </geometry>

          <surface>
            <friction>
              <ode>
                <mu>0.1</mu>
                <mu2>0.1</mu2>
                <slip1>0.8</slip1>
                <slip2>0.6</slip2>
              </ode>
            </friction>
          </surface>
        </collision>

        <!--<visual name='caster_fl_visual'>
          <pose>0.1825 -0.14 0.035 0 0 0</pose>
          <geometry>
            <sphere>
              <radius>.0375</radius>
            </sphere>
          </geometry>
        </visual>-->

        <collision name='caster_rl_collision'>
          <pose>-0.1825 -0.14 0.035 0 0 0</pose>
          <geometry>
              <sphere>
              <radius>.0375</radius>
            </sphere>
          </geometry>

          <surface>
            <friction>
              <ode>
                <mu>0.1</mu>
                <mu2>0.1</mu2>
                <slip1>0.8</slip1>
                <slip2>0.6</slip2>
              </ode>
            </friction>
          </surface>
        </collision>

        <!--<visual name='caster_rl_visual'>
          <pose>-0.1825 -0.14 0.035 0 0 0</pose>
          <geometry>
            <sphere>
              <radius>.0375</radius>
            </sphere>
          </geometry>
        </visual>-->

        <collision name='caster_rr_collision'>
          <pose>-0.1825 0.14 0.035 0 0 0</pose>
          <geometry>
              <sphere>
              <radius>.0375</radius>
            </sphere>
          </geometry>

          <surface>
            <friction>
              <ode>
                <mu>0.1</mu>
                <mu2>0.1</mu2>
                <slip1>0.8</slip1>
                <slip2>0.6</slip2>
              </ode>
            </friction>
          </surface>
        </collision>

        <!--<visual name='caster_rr_visual'>
          <pose>-0.1825 0.14 0.035 0 0 0</pose>
          <geometry>
            <sphere>
              <radius>.0375</radius>
            </sphere>
          </geometry>
        </visual>-->

      </link>


      <link name="left_wheel">
        <pose>0 0.239 0.09995 0 1.5707 0</pose>
        <collision name="collision">
          <pose>0 0.01 0 0 1.5707 1.5707</pose>
          <geometry>
            <cylinder>
              <radius>.104</radius>
              <length>.05</length>
            </cylinder>
          </geometry>
        </collision>
        <visual name="visual">
          <geometry>
            <mesh>
              <scale>1 1 1</scale>
              <uri>model://mrp2/meshes/left_wheel.stl</uri>
            </mesh>
          </geometry>
          <material>
            <script>
              <name>Gazebo/Grey</name>
            </script>
          </material>
        </visual>
      </link>

      <link name="right_wheel">
        <pose>0 -0.239 0.09995 0 1.5707 3.1415</pose>
        <collision name="collision">
          <pose>0 0.01 0 0 1.5707 1.5707</pose>
          <geometry>
            <cylinder>
              <radius>.104</radius>
              <length>.05</length>
            </cylinder>
          </geometry>
        </collision>
        <visual name="visual">
          <geometry>
            <mesh>
              <scale>1 1 1</scale>
              <uri>model://mrp2/meshes/left_wheel.stl</uri>
            </mesh>
          </geometry>
          <material>
            <script>
              <name>Gazebo/Grey</name>
            </script>
          </material>
        </visual>
      </link>
      <joint type="revolute" name="left_wheel_hinge">
        <pose>0 0 0 0 0 0</pose>
        <child>left_wheel</child>
        <parent>chassis</parent>
        <axis>
          <xyz>0 1 0</xyz>
        </axis>
      </joint>

      <joint type="revolute" name="right_wheel_hinge">
        <pose>0 0 0 0 0 0</pose>
        <child>right_wheel</child>
        <parent>chassis</parent>
        <axis>
          <xyz>0 1 0</xyz>
        </axis>
      </joint>
    </model>
  </sdf>
